Traceback (most recent call last):
  File "D:\micon\envs\jbooks\lib\site-packages\jupyter_cache\executors\utils.py", line 56, in single_nb_execution
    record_timing=False,
  File "D:\micon\envs\jbooks\lib\site-packages\nbclient\client.py", line 1204, in execute
    return NotebookClient(nb=nb, resources=resources, km=km, **kwargs).execute()
  File "D:\micon\envs\jbooks\lib\site-packages\nbclient\util.py", line 84, in wrapped
    return just_run(coro(*args, **kwargs))
  File "D:\micon\envs\jbooks\lib\site-packages\nbclient\util.py", line 62, in just_run
    return loop.run_until_complete(coro)
  File "D:\micon\envs\jbooks\lib\asyncio\base_events.py", line 587, in run_until_complete
    return future.result()
  File "D:\micon\envs\jbooks\lib\site-packages\nbclient\client.py", line 664, in async_execute
    cell, index, execution_count=self.code_cells_executed + 1
  File "D:\micon\envs\jbooks\lib\site-packages\nbclient\client.py", line 965, in async_execute_cell
    await self._check_raise_for_error(cell, cell_index, exec_reply)
  File "D:\micon\envs\jbooks\lib\site-packages\nbclient\client.py", line 862, in _check_raise_for_error
    raise CellExecutionError.from_cell_and_msg(cell, exec_reply_content)
nbclient.exceptions.CellExecutionError: An error occurred while executing the following cell:
------------------
import mysql.connector

mydb = mysql.connector.connect(
  host="localhost",
  user="root",
  passwd="rinintha"
)

print(mydb)
------------------

[1;31m---------------------------------------------------------------------------[0m
[1;31mMySQLInterfaceError[0m                       Traceback (most recent call last)
[1;32mD:\micon\envs\jbooks\lib\site-packages\mysql\connector\connection_cext.py[0m in [0;36m_open_connection[1;34m(self)[0m
[0;32m    245[0m         [1;32mtry[0m[1;33m:[0m[1;33m[0m[1;33m[0m[0m
[1;32m--> 246[1;33m             [0mself[0m[1;33m.[0m[0m_cmysql[0m[1;33m.[0m[0mconnect[0m[1;33m([0m[1;33m**[0m[0mcnx_kwargs[0m[1;33m)[0m[1;33m[0m[1;33m[0m[0m
[0m[0;32m    247[0m             [0mself[0m[1;33m.[0m[0m_cmysql[0m[1;33m.[0m[0mconverter_str_fallback[0m [1;33m=[0m [0mself[0m[1;33m.[0m[0m_converter_str_fallback[0m[1;33m[0m[1;33m[0m[0m

[1;31mMySQLInterfaceError[0m: Can't connect to MySQL server on 'localhost:3306' (10061)

During handling of the above exception, another exception occurred:

[1;31mDatabaseError[0m                             Traceback (most recent call last)
[1;32m~\AppData\Local\Temp\ipykernel_40908\3713277245.py[0m in [0;36m<module>[1;34m[0m
[0;32m      4[0m   [0mhost[0m[1;33m=[0m[1;34m"localhost"[0m[1;33m,[0m[1;33m[0m[1;33m[0m[0m
[0;32m      5[0m   [0muser[0m[1;33m=[0m[1;34m"root"[0m[1;33m,[0m[1;33m[0m[1;33m[0m[0m
[1;32m----> 6[1;33m   [0mpasswd[0m[1;33m=[0m[1;34m"rinintha"[0m[1;33m[0m[1;33m[0m[0m
[0m[0;32m      7[0m )
[0;32m      8[0m [1;33m[0m[0m

[1;32mD:\micon\envs\jbooks\lib\site-packages\mysql\connector\__init__.py[0m in [0;36mconnect[1;34m(*args, **kwargs)[0m
[0;32m    270[0m [1;33m[0m[0m
[0;32m    271[0m     [1;32mif[0m [0mHAVE_CEXT[0m [1;32mand[0m [1;32mnot[0m [0muse_pure[0m[1;33m:[0m[1;33m[0m[1;33m[0m[0m
[1;32m--> 272[1;33m         [1;32mreturn[0m [0mCMySQLConnection[0m[1;33m([0m[1;33m*[0m[0margs[0m[1;33m,[0m [1;33m**[0m[0mkwargs[0m[1;33m)[0m[1;33m[0m[1;33m[0m[0m
[0m[0;32m    273[0m     [1;32mreturn[0m [0mMySQLConnection[0m[1;33m([0m[1;33m*[0m[0margs[0m[1;33m,[0m [1;33m**[0m[0mkwargs[0m[1;33m)[0m[1;33m[0m[1;33m[0m[0m
[0;32m    274[0m [0mConnect[0m [1;33m=[0m [0mconnect[0m  [1;31m# pylint: disable=C0103[0m[1;33m[0m[1;33m[0m[0m

[1;32mD:\micon\envs\jbooks\lib\site-packages\mysql\connector\connection_cext.py[0m in [0;36m__init__[1;34m(self, **kwargs)[0m
[0;32m     92[0m [1;33m[0m[0m
[0;32m     93[0m         [1;32mif[0m [0mkwargs[0m[1;33m:[0m[1;33m[0m[1;33m[0m[0m
[1;32m---> 94[1;33m             [0mself[0m[1;33m.[0m[0mconnect[0m[1;33m([0m[1;33m**[0m[0mkwargs[0m[1;33m)[0m[1;33m[0m[1;33m[0m[0m
[0m[0;32m     95[0m [1;33m[0m[0m
[0;32m     96[0m     [1;32mdef[0m [0m_add_default_conn_attrs[0m[1;33m([0m[0mself[0m[1;33m)[0m[1;33m:[0m[1;33m[0m[1;33m[0m[0m

[1;32mD:\micon\envs\jbooks\lib\site-packages\mysql\connector\abstracts.py[0m in [0;36mconnect[1;34m(self, **kwargs)[0m
[0;32m   1050[0m [1;33m[0m[0m
[0;32m   1051[0m         [0mself[0m[1;33m.[0m[0mdisconnect[0m[1;33m([0m[1;33m)[0m[1;33m[0m[1;33m[0m[0m
[1;32m-> 1052[1;33m         [0mself[0m[1;33m.[0m[0m_open_connection[0m[1;33m([0m[1;33m)[0m[1;33m[0m[1;33m[0m[0m
[0m[0;32m   1053[0m         [1;31m# Server does not allow to run any other statement different from ALTER[0m[1;33m[0m[1;33m[0m[1;33m[0m[0m
[0;32m   1054[0m         [1;31m# when user's password has been expired.[0m[1;33m[0m[1;33m[0m[1;33m[0m[0m

[1;32mD:\micon\envs\jbooks\lib\site-packages\mysql\connector\connection_cext.py[0m in [0;36m_open_connection[1;34m(self)[0m
[0;32m    250[0m         [1;32mexcept[0m [0mMySQLInterfaceError[0m [1;32mas[0m [0mexc[0m[1;33m:[0m[1;33m[0m[1;33m[0m[0m
[0;32m    251[0m             raise errors.get_mysql_exception(msg=exc.msg, errno=exc.errno,
[1;32m--> 252[1;33m                                              sqlstate=exc.sqlstate)
[0m[0;32m    253[0m [1;33m[0m[0m
[0;32m    254[0m         [0mself[0m[1;33m.[0m[0m_do_handshake[0m[1;33m([0m[1;33m)[0m[1;33m[0m[1;33m[0m[0m

[1;31mDatabaseError[0m: 2003 (HY000): Can't connect to MySQL server on 'localhost:3306' (10061)
DatabaseError: 2003 (HY000): Can't connect to MySQL server on 'localhost:3306' (10061)

